<mujoco model="inverted_pendulum">
    <compiler inertiafromgeom="true"/>
    <default>
        <joint armature="0.01" damping="1"/>
        <geom friction="1 0.1 0.1"/>
    </default>

    <worldbody>
        <body name="cart" pos="0 0 0">
            <joint name="slider" type="slide" axis="1 0 0"/>
            <geom name="cart_geom" type="box" size="0.1 0.1 0.05"/>

            <body name="pole" pos="0 0 0.1">
                <joint name="hinge" type="hinge" axis="0 1 0"/>
                <geom name="pole_geom" type="capsule" size="0.02 0.3" fromto="0 0 0 0 0 0.6"/>
            </body>
        </body>
    </worldbody>
</mujoco>

